<!DOCTYPE html>
<html lang="en">

<head>
  <meta charset="UTF-8">
  <meta name="viewport" content="width=device-width, initial-scale=1.0">
  <meta http-equiv="X-UA-Compatible" content="ie=edge">
  <title>Document</title>
</head>

<body>
  <script>
    /**
     * Promise.prototype.catch()
     * Promise.prototype.catch方法是.then(null, rejection)或.then(undefined, rejection)的别名，用于指定发生错误时的回调函数。
     * getJSON方法返回一个 Promise 对象，如果该对象状态变为resolved，则会调用then方法指定的回调函数；
     * 如果异步操作抛出错误，状态就会变为rejected，就会调用catch方法指定的回调函数，处理这个错误。另外，then方法指定的回调函数，如果运行中抛出错误，也会被catch方法捕获。
     * **/
    {
      // getJSON('/posts.json').then(function (posts) {
      //   // ...
      // }).catch(function (error) {
      //   // 处理 getJSON 和 前一个回调函数运行时发生的错误
      //   console.log('发生错误！', error);
      // });

      // p.then((val) => console.log('fulfilled:', val))
      //   .catch((err) => console.log('rejected', err));

      // // 等同于
      // p.then((val) => console.log('fulfilled:', val))
      //   .then(null, (err) => console.log("rejected:", err));
    }

    {
      // promise抛出一个错误，就被catch方法指定的回调函数捕获
      // 写法一
      const promise1 = new Promise(function (resolve, reject) {
        try {
          throw new Error('test')
        } catch (e) {
          reject(e)
        }
      });
      promise1.catch(function (error) {
        console.log(error);
      });

      // 写法二
      const promise2 = new Promise(function (resolve, reject) {
        reject(new Error('test'));
      });
      promise2.catch(function (error) {
        console.log(error);
      });
    }

    {
      // 如果 Promise 状态已经变成resolved，再抛出错误是无效的。
      const promise = new Promise(function (resolve, reject) {
        resolve('ok');
        throw new Error('test')
      });
      promise.then(function (value) { console.log(value) }).catch(function (error) { console.log(error) });
      // Promise 在resolve语句后面，再抛出错误，不会被捕获，等于没有抛出。因为 Promise 的状态一旦改变，就永久保持该状态，不会再变了。
      // ok
    }

    {
      // Promise 对象的错误具有“冒泡”性质，会一直向后传递，直到被捕获为止。getJSON('/post/1.json').then(function(post) {
      // getJSON('/post/1.json').then(function (post) {
      //   return getJSON(post.commentURL);
      // }).then(function (comments) {
      //   // some code
      // }).catch(function (error) {
      //   // 处理前面三个Promise产生的错误
      // });
    }

    {
      // 一般来说，不要在then方法里面定义 Reject 状态的回调函数（即then的第二个参数），总是使用catch方法。
      // 第二种写法要好于第一种写法，理由是第二种写法可以捕获前面then方法执行中的错误，也更接近同步的写法（try/catch）。因此，建议总是使用catch方法，而不使用then方法的第二个参数。
      // bad
      // promise
      //   .then(function (data) {
      //     // success
      //   }, function (err) {
      //     // error
      //   });

      // good
      promise
        .then(function (data) { //cb
          // success
        })
        .catch(function (err) {
          // error
        });
    }
  </script>
</body>

</html>