<!DOCTYPE html>
<html lang="en">

<head>
  <meta charset="UTF-8">
  <meta name="viewport" content="width=device-width, initial-scale=1.0">
  <meta http-equiv="X-UA-Compatible" content="ie=edge">
  <title>Document</title>
</head>

<body>
  <script>
    /**
     * 语法
     **/
    {
      // 返回Promise对象, async函数返回一个 Promise 对象。async函数内部return语句返回的值，会成为then方法回调函数的参数。
      async function f() {
        return 'hello world';
      }
      f().then(v => console.log(v));
      // 函数f内部return命令返回的值，会被then方法回调函数接收到
      // hello world

      // async函数内部抛出错误，会导致返回的 Promise 对象变为reject状态。抛出的错误对象会被catch方法回调函数接收到。
      async function f1() {
        throw new Error('出错了');
      }
      f1().then(
        v => console.log(v),
        e => console.log(e)
      )
      // 出错了
    }

    {
      // Promise对象的状态变化
      // async函数返回的 Promise 对象，必须等到内部所有await命令后面的 Promise 对象执行完，才会发生状态改变，除非遇到return语句或者抛出错误。
      // async function getTitle(url) {
      //   let response = await fetch(url);
      //   let html = await response.text();
      //   return html.match(/<title>([\s\S]+)<\/title>/i)[1];
      // }
      // getTitle('https://tc39.github.io/ecma262/').then(console.log)
      // "ECMAScript 2017 Language Specification"
      // 函数getTitle内部有三个操作：抓取网页、取出文本、匹配页面标题。只有这三个操作全部完成，才会执行then方法里面的console.log。
    }

    {
      // await命令
      // 正常情况下，await命令后面是一个 Promise 对象，返回该对象的结果。如果不是 Promise 对象，就直接返回对应的值。
      async function f() {
        // 等同于
        // return 123;
        return await 123;
      }

      f().then(v => console.log(v));
      // 123

      // 另一种情况是，await命令后面是一个thenable对象（即定义then方法的对象），那么await会将其等同于 Promise 对象。
      class Sleep {
        constructor(timeout) {
          this.timeout = timeout;
        }
        then(resolve, reject) {
          const startTime = Date.now();
          setTimeout(() => {
            resolve(Date.now() - startTime);
          }, this.timeout);
        }
      }

      (async () => {
        const sleepTime = await new Sleep(1000);
        console.log(sleepTime);
      })();
    }

    {
      // 错误处理
      // 如果await后面的异步操作出错，那么等同于async函数返回的 Promise 对象被reject。
      async function f() {
        await new Promise(function (resolve, reject) {
          throw new Error('出错了');
        });
      }

      f()
        .then(v => console.log(v))
        .catch(e => console.log(e))
      // 上面代码中，async函数f执行后，await后面的 Promise 对象会抛出一个错误对象，导致catch方法的回调函数被调用，它的参数就是抛出的错误对象。
      // Error：出错了
    }
  </script>
</body>

</html>